Workbook

Sheet Summary
A1: Water Quality Monitoring — Summary
A3: Generated | B3: 2026-07-22 10:20:21
A4: Sample / ID | B4: CALF-20 wash batch 3
A5: Data span | B5: 2026-07-21 17:19:31 — 2026-07-22 10:20:20
A6: Duration | B6: 0 days 17:00:49
A7: Raw points | B7: 30630
A8: 1-min points | B8: 1022
A9: EC cal factor | B9: 1.0367
A10: pH filter | B10: median(3) + moving average(3)
A12: Summary Statistics (1-min averaged)
A13: Parameter | B13: Unit | C13: n | D13: Mean | E13: SD | F13: SE | G13: RSD% | H13: Min | I13: Max | J13: Range | K13: 95% CI low | L13: 95% CI high
A14: EC | B14: µS/cm | C14: 1022 | D14: 221.72 | E14: 0.58 | F14: 0.02 | G14: 0.26 | H14: 219.51 | I14: 222.63 | J14: 3.12 | K14: 221.69 | L14: 221.76
A15: pH | C15: 1022 | D15: 6.76 | E15: 0 | F15: 0 | G15: 0.06 | H15: 6.75 | I15: 6.77 | J15: 0.03 | K15: 6.76 | L15: 6.76
A16: Water T | B16: °C | C16: 1022 | D16: 20.81 | E16: 0.55 | F16: 0.02 | G16: 2.66 | H16: 20 | I16: 22.2 | J16: 2.2 | K16: 20.77 | L16: 20.84
A17: Salinity | B17: ppm | C17: 1022 | D17: 105 | E17: 0 | F17: 0 | G17: 0.34 | H17: 104 | I17: 105 | J17: 1 | K17: 105 | L17: 105
A18: TDS | B18: ppm | C18: 1022 | D18: 105 | E18: 0 | F18: 0 | G18: 0.34 | H18: 104 | I18: 105 | J18: 1 | K18: 105 | L18: 105
A19: pH raw | B19: mV | C19: 1022 | D19: 1567 | E19: 1 | F19: 0 | G19: 0.06 | H19: 1564 | I19: 1570 | J19: 6 | K19: 1566 | L19: 1567

Sheet 1min_avg
A1: timestamp | B1: time_s | C1: EC_uScm | D1: Tw_C | E1: Salinity_ppm | F1: TDS_ppm | G1: pH | H1: pH_mV | I1: rs485_ok
A2: 2026-07-21 17:19:00 | B2: -31 | C2: 220.2 | D2: 22.2 | E2: 104 | F2: 104 | G2: 6.7566111 | H2: 1568.3333 | I2: 1
A3: 2026-07-21 17:20:00 | B3: 29 | C3: 220.32333 | D3: 22.2 | E3: 103.93333 | F3: 103.93333 | G3: 6.7592222 | H3: 1567.5667 | I3: 1
A4: 2026-07-21 17:21:00 | B4: 89 | C4: 220.25333 | D4: 22.18 | E4: 103.93333 | F4: 103.93333 | G4: 6.7573333 | H4: 1567.9667 | I4: 1
A5: 2026-07-21 17:22:00 | B5: 149 | C5: 220.45333 | D5: 22.1 | E5: 104 | F5: 104 | G5: 6.7563333 | H5: 1568.3 | I5: 1
A6: 2026-07-21 17:23:00 | B6: 209 | C6: 220.29333 | D6: 22.1 | E6: 103.93333 | F6: 103.93333 | G6: 6.7573333 | H6: 1567.7667 | I6: 1
A7: 2026-07-21 17:24:00 | B7: 269 | C7: 219.50667 | D7: 22.1 | E7: 103.56667 | F7: 103.56667 | G7: 6.758 | H7: 1567.8333 | I7: 1
A8: 2026-07-21 17:25:00 | B8: 329 | C8: 220.29 | D8: 22.1 | E8: 103.96667 | F8: 103.96667 | G8: 6.7576667 | H8: 1568.0333 | I8: 1
A9: 2026-07-21 17:26:00 | B9: 389 | C9: 220.17333 | D9: 22.1 | E9: 103.93333 | F9: 103.93333 | G9: 6.7593333 | H9: 1567.6333 | I9: 1
A10: 2026-07-21 17:27:00 | B10: 449 | C10: 219.91667 | D10: 22.1 | E10: 103.9 | F10: 103.9 | G10: 6.757 | H10: 1567.7667 | I10: 1
A11: 2026-07-21 17:28:00 | B11: 509 | C11: 219.99 | D11: 22.1 | E11: 103.86667 | F11: 103.86667 | G11: 6.7593333 | H11: 1567.5667 | I11: 1
A12: 2026-07-21 17:29:00 | B12: 569 | C12: 220.40333 | D12: 22.04 | E12: 104 | F12: 104 | G12: 6.7576667 | H12: 1567.9 | I12: 1
A13: 2026-07-21 17:30:00 | B13: 629 | C13: 220.26667 | D13: 22 | E13: 103.9 | F13: 103.9 | G13: 6.763 | H13: 1567.0333 | I13: 1
... A1023: 2026-07-22 10:20:00 | B1023: 61229 | C1023: 222.6 | D1023: 20.2 | E1023: 105 | F1023: 105 | G1023: 6.7663636 | H1023: 1565.8182 | I1023: 1

Sheet EC_slope
A1: EC vs Time — Slope / Rate-of-Change Analysis
A2: Source: 1min_avg (n=1022, 0–17.0 h). Slope units = µS/cm per hour.
A4: 1) Piecewise linear fit (segment-by-segment) | N4: 2) Rolling slope (31-min centred window)
A5: Segment | B5: Start (h) | C5: End (h) | D5: Row start | E5: Row end | F5: n pts | G5: EC start | H5: EC end | I5: ΔEC | J5: Slope (µS/cm/h) | K5: R² | L5: vs. prev segment | M5: Intercept | N5: Time (h) | O5: EC (µS/cm) | P5: Slope 31min (µS/cm/h) | Q5: Slope 2h (µS/cm/h) | R5: Piecewise fit (µS/cm)
A6: S1 | B6: 0 | C6: 0.5 | D6: =MATCH($B6*3600,'1min_avg'!$B:$B,1) -> 2 | E6: =MATCH($C6*3600,'1min_avg'!$B:$B,1) -> 32 | F6: =$E6-$D6+1 -> 31 | G6: {=INDEX('1min_avg'!$C:$C,$D6)} -> 220.2 | H6: {=INDEX('1min_avg'!$C:$C,$E6)} -> 220.65 | I6: =$H6-$G6 -> 0.45 | J6: =SLOPE(INDEX('1min_avg'!$C:$C,$D6):INDEX('1min_avg'!$C:$C,$E6),INDEX('1min_avg'!$B:$B,$D6):INDEX('1min_avg'!$B:$B,$E6))*3600 -> 0.98137097 | K6: =RSQ(INDEX('1min_avg'!$C:$C,$D6):INDEX('1min_avg'!$C:$C,$E6),INDEX('1min_avg'!$B:$B,$D6):INDEX('1min_avg'!$B:$B,$E6)) -> 0.336571 | M6: =INTERCEPT(INDEX('1min_avg'!$C:$C,$D6):INDEX('1min_avg'!$C:$C,$E6),INDEX('1min_avg'!$B:$B,$D6):INDEX('1min_avg'!$B:$B,$E6)) -> 220.12106 | N6: ='1min_avg'!B2/3600 -> -0.0086111111 | O6: ='1min_avg'!C2 -> 220.2 | R6: =INDEX($M$6:$M$15,MATCH(MAX(N6,0),$B$6:$B$15,1))+INDEX($J$6:$J$15,MATCH(MAX(N6,0),$B$6:$B$15,1))*MAX(N6,0) -> 220.12106
A7: S2 | B7: 0.5 | C7: 1 | D7: =MATCH($B7*3600,'1min_avg'!$B:$B,1) -> 32 | E7: =MATCH($C7*3600,'1min_avg'!$B:$B,1) -> 62 | F7: =$E7-$D7+1 -> 31 | G7: {=INDEX('1min_avg'!$C:$C,$D7)} -> 220.65 | H7: {=INDEX('1min_avg'!$C:$C,$E7)} -> 220.74667 | I7: =$H7-$G7 -> 0.096666667 | J7: =SLOPE(INDEX('1min_avg'!$C:$C,$D7):INDEX('1min_avg'!$C:$C,$E7),INDEX('1min_avg'!$B:$B,$D7):INDEX('1min_avg'!$B:$B,$E7))*3600 -> 0.10943548 | K7: =RSQ(INDEX('1min_avg'!$C:$C,$D7):INDEX('1min_avg'!$C:$C,$E7),INDEX('1min_avg'!$B:$B,$D7):INDEX('1min_avg'!$B:$B,$E7)) -> 0.024031171 | L7: =IF(J6=0,"",J7/J6-1) -> -0.88848714 | M7: =INTERCEPT(INDEX('1min_avg'!$C:$C,$D7):INDEX('1min_avg'!$C:$C,$E7),INDEX('1min_avg'!$B:$B,$D7):INDEX('1min_avg'!$B:$B,$E7)) -> 220.56833 | N7: ='1min_avg'!B3/3600 -> 0.0080555556 | O7: ='1min_avg'!C3 -> 220.32333 | R7: =INDEX($M$6:$M$15,MATCH(MAX(N7,0),$B$6:$B$15,1))+INDEX($J$6:$J$15,MATCH(MAX(N7,0),$B$6:$B$15,1))*MAX(N7,0) -> 220.12897
A8: S3 | B8: 1 | C8: 2 | D8: =MATCH($B8*3600,'1min_avg'!$B:$B,1) -> 62 | E8: =MATCH($C8*3600,'1min_avg'!$B:$B,1) -> 122 | F8: =$E8-$D8+1 -> 61 | G8: {=INDEX('1min_avg'!$C:$C,$D8)} -> 220.74667 | H8: {=INDEX('1min_avg'!$C:$C,$E8)} -> 220.99667 | I8: =$H8-$G8 -> 0.25 | J8: =SLOPE(INDEX('1min_avg'!$C:$C,$D8):INDEX('1min_avg'!$C:$C,$E8),INDEX('1min_avg'!$B:$B,$D8):INDEX('1min_avg'!$B:$B,$E8))*3600 -> 0.18257007 | K8: =RSQ(INDEX('1min_avg'!$C:$C,$D8):INDEX('1min_avg'!$C:$C,$E8),INDEX('1min_avg'!$B:$B,$D8):INDEX('1min_avg'!$B:$B,$E8)) -> 0.58716574 | L8: =IF(J7=0,"",J8/J7-1) -> 0.6682895 | M8: =INTERCEPT(INDEX('1min_avg'!$C:$C,$D8):INDEX('1min_avg'!$C:$C,$E8),INDEX('1min_avg'!$B:$B,$D8):INDEX('1min_avg'!$B:$B,$E8)) -> 220.60242 | N8: ='1min_avg'!B4/3600 -> 0.024722222 | O8: ='1min_avg'!C4 -> 220.25333 | R8: =INDEX($M$6:$M$15,MATCH(MAX(N8,0),$B$6:$B$15,1))+INDEX($J$6:$J$15,MATCH(MAX(N8,0),$B$6:$B$15,1))*MAX(N8,0) -> 220.14533
A9: S4 | B9: 2 | C9: 4 | D9: =MATCH($B9*3600,'1min_avg'!$B:$B,1) -> 122 | E9: =MATCH($C9*3600,'1min_avg'!$B:$B,1) -> 242 | F9: =$E9-$D9+1 -> 121 | G9: {=INDEX('1min_avg'!$C:$C,$D9)} -> 220.99667 | H9: {=INDEX('1min_avg'!$C:$C,$E9)} -> 221.27667 | I9: =$H9-$G9 -> 0.28 | J9: =SLOPE(INDEX('1min_avg'!$C:$C,$D9):INDEX('1min_avg'!$C:$C,$E9),INDEX('1min_avg'!$B:$B,$D9):INDEX('1min_avg'!$B:$B,$E9))*3600 -> 0.15895425 | K9: =RSQ(INDEX('1min_avg'!$C:$C,$D9):INDEX('1min_avg'!$C:$C,$E9),INDEX('1min_avg'!$B:$B,$D9):INDEX('1min_avg'!$B:$B,$E9)) -> 0.84881604 | L9: =IF(J8=0,"",J9/J8-1) -> -0.1293521 | M9: =INTERCEPT(INDEX('1min_avg'!$C:$C,$D9):INDEX('1min_avg'!$C:$C,$E9),INDEX('1min_avg'!$B:$B,$D9):INDEX('1min_avg'!$B:$B,$E9)) -> 220.62955 | N9: ='1min_avg'!B5/3600 -> 0.041388889 | O9: ='1min_avg'!C5 -> 220.45333 | R9: =INDEX($M$6:$M$15,MATCH(MAX(N9,0),$B$6:$B$15,1))+INDEX($J$6:$J$15,MATCH(MAX(N9,0),$B$6:$B$15,1))*MAX(N9,0) -> 220.16168
A10: S5 | B10: 4 | C10: 6 | D10: =MATCH($B10*3600,'1min_avg'!$B:$B,1) -> 242 | E10: =MATCH($C10*3600,'1min_avg'!$B:$B,1) -> 362 | F10: =$E10-$D10+1 -> 121 | G10: {=INDEX('1min_avg'!$C:$C,$D10)} -> 221.27667 | H10: {=INDEX('1min_avg'!$C:$C,$E10)} -> 221.53333 | I10: =$H10-$G10 -> 0.25666667 | J10: =SLOPE(INDEX('1min_avg'!$C:$C,$D10):INDEX('1min_avg'!$C:$C,$E10),INDEX('1min_avg'!$B:$B,$D10):INDEX('1min_avg'!$B:$B,$E10))*3600 -> 0.1377713 | K10: =RSQ(INDEX('1min_avg'!$C:$C,$D10):INDEX('1min_avg'!$C:$C,$E10),INDEX('1min_avg'!$B:$B,$D10):INDEX('1min_avg'!$B:$B,$E10)) -> 0.95364903 | L10: =IF(J9=0,"",J10/J9-1) -> -0.13326439 | M10: =INTERCEPT(INDEX('1min_avg'!$C:$C,$D10):INDEX('1min_avg'!$C:$C,$E10),INDEX('1min_avg'!$B:$B,$D10):INDEX('1min_avg'!$B:$B,$E10)) -> 220.71379 | N10: ='1min_avg'!B6/3600 -> 0.058055556 | O10: ='1min_avg'!C6 -> 220.29333 | R10: =INDEX($M$6:$M$15,MATCH(MAX(N10,0),$B$6:$B$15,1))+INDEX($J$6:$J$15,MATCH(MAX(N10,0),$B$6:$B$15,1))*MAX(N10,0) -> 220.17804
A11: S6 | B11: 6 | C11: 8 | D11: =MATCH($B11*3600,'1min_avg'!$B:$B,1) -> 362 | E11: =MATCH($C11*3600,'1min_avg'!$B:$B,1) -> 482 | F11: =$E11-$D11+1 -> 121 | G11: {=INDEX('1min_avg'!$C:$C,$D11)} -> 221.53333 | H11: {=INDEX('1min_avg'!$C:$C,$E11)} -> 221.79333 | I11: =$H11-$G11 -> 0.26 | J11: =SLOPE(INDEX('1min_avg'!$C:$C,$D11):INDEX('1min_avg'!$C:$C,$E11),INDEX('1min_avg'!$B:$B,$D11):INDEX('1min_avg'!$B:$B,$E11))*3600 -> 0.12297057 | K11: =RSQ(INDEX('1min_avg'!$C:$C,$D11):INDEX('1min_avg'!$C:$C,$E11),INDEX('1min_avg'!$B:$B,$D11):INDEX('1min_avg'!$B:$B,$E11)) -> 0.93445349 | L11: =IF(J10=0,"",J11/J10-1) -> -0.10742971 | M11: =INTERCEPT(INDEX('1min_avg'!$C:$C,$D11):INDEX('1min_avg'!$C:$C,$E11),INDEX('1min_avg'!$B:$B,$D11):INDEX('1min_avg'!$B:$B,$E11)) -> 220.82401 | N11: ='1min_avg'!B7/3600 -> 0.074722222 | O11: ='1min_avg'!C7 -> 219.50667 | R11: =INDEX($M$6:$M$15,MATCH(MAX(N11,0),$B$6:$B$15,1))+INDEX($J$6:$J$15,MATCH(MAX(N11,0),$B$6:$B$15,1))*MAX(N11,0) -> 220.1944
A12: S7 | B12: 8 | C12: 10 | D12: =MATCH($B12*3600,'1min_avg'!$B:$B,1) -> 482 | E12: =MATCH($C12*3600,'1min_avg'!$B:$B,1) -> 602 | F12: =$E12-$D12+1 -> 121 | G12: {=INDEX('1min_avg'!$C:$C,$D12)} -> 221.79333 | H12: {=INDEX('1min_avg'!$C:$C,$E12)} -> 221.90667 | I12: =$H12-$G12 -> 0.11333333 | J12: =SLOPE(INDEX('1min_avg'!$C:$C,$D12):INDEX('1min_avg'!$C:$C,$E12),INDEX('1min_avg'!$B:$B,$D12):INDEX('1min_avg'!$B:$B,$E12))*3600 -> 0.069891614 | K12: =RSQ(INDEX('1min_avg'!$C:$C,$D12):INDEX('1min_avg'!$C:$C,$E12),INDEX('1min_avg'!$B:$B,$D12):INDEX('1min_avg'!$B:$B,$E12)) -> 0.85551617 | L12: =IF(J11=0,"",J12/J11-1) -> -0.43163953 | M12: =INTERCEPT(INDEX('1min_avg'!$C:$C,$D12):INDEX('1min_avg'!$C:$C,$E12),INDEX('1min_avg'!$B:$B,$D12):INDEX('1min_avg'!$B:$B,$E12)) -> 221.2272 | N12: ='1min_avg'!B8/3600 -> 0.091388889 | O12: ='1min_avg'!C8 -> 220.29 | R12: =INDEX($M$6:$M$15,MATCH(MAX(N12,0),$B$6:$B$15,1))+INDEX($J$6:$J$15,MATCH(MAX(N12,0),$B$6:$B$15,1))*MAX(N12,0) -> 220.21075
A13: S8 | B13: 10 | C13: 12 | D13: =MATCH($B13*3600,'1min_avg'!$B:$B,1) -> 602 | E13: =MATCH($C13*3600,'1min_avg'!$B:$B,1) -> 722 | F13: =$E13-$D13+1 -> 121 | G13: {=INDEX('1min_avg'!$C:$C,$D13)} -> 221.90667 | H13: {=INDEX('1min_avg'!$C:$C,$E13)} -> 222.1 | I13: =$H13-$G13 -> 0.19333333 | J13: =SLOPE(INDEX('1min_avg'!$C:$C,$D13):INDEX('1min_avg'!$C:$C,$E13),INDEX('1min_avg'!$B:$B,$D13):INDEX('1min_avg'!$B:$B,$E13))*3600 -> 0.099961671 | K13: =RSQ(INDEX('1min_avg'!$C:$C,$D13):INDEX('1min_avg'!$C:$C,$E13),INDEX('1min_avg'!$B:$B,$D13):INDEX('1min_avg'!$B:$B,$E13)) -> 0.90949277 | L13: =IF(J12=0,"",J13/J12-1) -> 0.43023843 | M13: =INTERCEPT(INDEX('1min_avg'!$C:$C,$D13):INDEX('1min_avg'!$C:$C,$E13),INDEX('1min_avg'!$B:$B,$D13):INDEX('1min_avg'!$B:$B,$E13)) -> 220.92706 | N13: ='1min_avg'!B9/3600 -> 0.10805556 | O13: ='1min_avg'!C9 -> 220.17333 | R13: =INDEX($M$6:$M$15,MATCH(MAX(N13,0),$B$6:$B$15,1))+INDEX($J$6:$J$15,MATCH(MAX(N13,0),$B$6:$B$15,1))*MAX(N13,0) -> 220.22711
A14: S9 | B14: 12 | C14: 14 | D14: =MATCH($B14*3600,'1min_avg'!$B:$B,1) -> 722 | E14: =MATCH($C14*3600,'1min_avg'!$B:$B,1) -> 842 | F14: =$E14-$D14+1 -> 121 | G14: {=INDEX('1min_avg'!$C:$C,$D14)} -> 222.1 | H14: {=INDEX('1min_avg'!$C:$C,$E14)} -> 222.31 | I14: =$H14-$G14 -> 0.21 | J14: =SLOPE(INDEX('1min_avg'!$C:$C,$D14):INDEX('1min_avg'!$C:$C,$E14),INDEX('1min_avg'!$B:$B,$D14):INDEX('1min_avg'!$B:$B,$E14))*3600 -> 0.12351443 | K14: =RSQ(INDEX('1min_avg'!$C:$C,$D14):INDEX('1min_avg'!$C:$C,$E14),INDEX('1min_avg'!$B:$B,$D14):INDEX('1min_avg'!$B:$B,$E14)) -> 0.92051739 | L14: =IF(J13=0,"",J14/J13-1) -> 0.23561788 | M14: =INTERCEPT(INDEX('1min_avg'!$C:$C,$D14):INDEX('1min_avg'!$C:$C,$E14),INDEX('1min_avg'!$B:$B,$D14):INDEX('1min_avg'!$B:$B,$E14)) -> 220.60279 | N14: ='1min_avg'!B10/3600 -> 0.12472222 | O14: ='1min_avg'!C10 -> 219.91667 | R14: =INDEX($M$6:$M$15,MATCH(MAX(N14,0),$B$6:$B$15,1))+INDEX($J$6:$J$15,MATCH(MAX(N14,0),$B$6:$B$15,1))*MAX(N14,0) -> 220.24346
A15: S10 | B15: 14 | C15: 17.01 | D15: =MATCH($B15*3600,'1min_avg'!$B:$B,1) -> 842 | E15: =MATCH($C15*3600,'1min_avg'!$B:$B,1) -> 1023 | F15: =$E15-$D15+1 -> 182 | G15: {=INDEX('1min_avg'!$C:$C,$D15)} -> 222.31 | H15: {=INDEX('1min_avg'!$C:$C,$E15)} -> 222.6 | I15: =$H15-$G15 -> 0.29 | J15: =SLOPE(INDEX('1min_avg'!$C:$C,$D15):INDEX('1min_avg'!$C:$C,$E15),INDEX('1min_avg'!$B:$B,$D15):INDEX('1min_avg'!$B:$B,$E15))*3600 -> 0.084851208 | K15: =RSQ(INDEX('1min_avg'!$C:$C,$D15):INDEX('1min_avg'!$C:$C,$E15),INDEX('1min_avg'!$B:$B,$D15):INDEX('1min_avg'!$B:$B,$E15)) -> 0.79990632 | L15: =IF(J14=0,"",J15/J14-1) -> -0.31302595 | M15: =INTERCEPT(INDEX('1min_avg'!$C:$C,$D15):INDEX('1min_avg'!$C:$C,$E15),INDEX('1min_avg'!$B:$B,$D15):INDEX('1min_avg'!$B:$B,$E15)) -> 221.1441 | N15: ='1min_avg'!B11/3600 -> 0.14138889 | O15: ='1min_avg'!C11 -> 219.99 | R15: =INDEX($M$6:$M$15,MATCH(MAX(N15,0),$B$6:$B$15,1))+INDEX($J$6:$J$15,MATCH(MAX(N15,0),$B$6:$B$15,1))*MAX(N15,0) -> 220.25982
A16: How to read: J = slope of a straight line fitted to that segment; K = R² (how linear that segment is); L = % change in slope vs the previous segment. | N16: ='1min_avg'!B12/3600 -> 0.15805556 | O16: ='1min_avg'!C12 -> 220.40333 | R16: =INDEX($M$6:$M$15,MATCH(MAX(N16,0),$B$6:$B$15,1))+INDEX($J$6:$J$15,MATCH(MAX(N16,0),$B$6:$B$15,1))*MAX(N16,0) -> 220.27618
N17: ='1min_avg'!B13/3600 -> 0.17472222 | O17: ='1min_avg'!C13 -> 220.26667 | R17: =INDEX($M$6:$M$15,MATCH(MAX(N17,0),$B$6:$B$15,1))+INDEX($J$6:$J$15,MATCH(MAX(N17,0),$B$6:$B$15,1))*MAX(N17,0) -> 220.29253
N18: ='1min_avg'!B14/3600 -> 0.19138889 | O18: ='1min_avg'!C14 -> 220.34 | R18: =INDEX($M$6:$M$15,MATCH(MAX(N18,0),$B$6:$B$15,1))+INDEX($J$6:$J$15,MATCH(MAX(N18,0),$B$6:$B$15,1))*MAX(N18,0) -> 220.30889
N19: ='1min_avg'!B15/3600 -> 0.20805556 | O19: ='1min_avg'!C15 -> 220.37333 | R19: =INDEX($M$6:$M$15,MATCH(MAX(N19,0),$B$6:$B$15,1))+INDEX($J$6:$J$15,MATCH(MAX(N19,0),$B$6:$B$15,1))*MAX(N19,0) -> 220.32524
N20: ='1min_avg'!B16/3600 -> 0.22472222 | O20: ='1min_avg'!C16 -> 220.48667 | R20: =INDEX($M$6:$M$15,MATCH(MAX(N20,0),$B$6:$B$15,1))+INDEX($J$6:$J$15,MATCH(MAX(N20,0),$B$6:$B$15,1))*MAX(N20,0) -> 220.3416
N21: ='1min_avg'!B17/3600 -> 0.24138889 | O21: ='1min_avg'!C17 -> 220.41667 | P21: =SLOPE(O6:O36,N6:N36) -> 0.98137097 | R21: =INDEX($M$6:$M$15,MATCH(MAX(N21,0),$B$6:$B$15,1))+INDEX($J$6:$J$15,MATCH(MAX(N21,0),$B$6:$B$15,1))*MAX(N21,0) -> 220.35796
N22: ='1min_avg'!B18/3600 -> 0.25805556 | O22: ='1min_avg'!C18 -> 220.39333 | P22: =SLOPE(O7:O37,N7:N37) -> 1.0733871 | R22: =INDEX($M$6:$M$15,MATCH(MAX(N22,0),$B$6:$B$15,1))+INDEX($J$6:$J$15,MATCH(MAX(N22,0),$B$6:$B$15,1))*MAX(N22,0) -> 220.37431
N23: ='1min_avg'!B19/3600 -> 0.27472222 | O23: ='1min_avg'!C19 -> 220 | P23: =SLOPE(O8:O38,N8:N38) -> 1.1567742 | R23: =INDEX($M$6:$M$15,MATCH(MAX(N23,0),$B$6:$B$15,1))+INDEX($J$6:$J$15,MATCH(MAX(N23,0),$B$6:$B$15,1))*MAX(N23,0) -> 220.39067
N24: ='1min_avg'!B20/3600 -> 0.29138889 | O24: ='1min_avg'!C20 -> 220.55 | P24: =SLOPE(O9:O39,N9:N39) -> 1.2217742 | R24: =INDEX($M$6:$M$15,MATCH(MAX(N24,0),$B$6:$B$15,1))+INDEX($J$6:$J$15,MATCH(MAX(N24,0),$B$6:$B$15,1))*MAX(N24,0) -> 220.40703
N25: ='1min_avg'!B21/3600 -> 0.30805556 | O25: ='1min_avg'!C21 -> 220.55 | P25: =SLOPE(O10:O40,N10:N40) -> 1.3216935 | R25: =INDEX($M$6:$M$15,MATCH(MAX(N25,0),$B$6:$B$15,1))+INDEX($J$6:$J$15,MATCH(MAX(N25,0),$B$6:$B$15,1))*MAX(N25,0) -> 220.42338
N26: ='1min_avg'!B22/3600 -> 0.32472222 | O26: ='1min_avg'!C22 -> 220.52667 | P26: =SLOPE(O11:O41,N11:N41) -> 1.3241129 | R26: =INDEX($M$6:$M$15,MATCH(MAX(N26,0),$B$6:$B$15,1))+INDEX($J$6:$J$15,MATCH(MAX(N26,0),$B$6:$B$15,1))*MAX(N26,0) -> 220.43974
N27: ='1min_avg'!B23/3600 -> 0.34138889 | O27: ='1min_avg'!C23 -> 220.53667 | P27: =SLOPE(O12:O42,N12:N42) -> 1.0475806 | R27: =INDEX($M$6:$M$15,MATCH(MAX(N27,0),$B$6:$B$15,1))+INDEX($J$6:$J$15,MATCH(MAX(N27,0),$B$6:$B$15,1))*MAX(N27,0) -> 220.45609
N28: ='1min_avg'!B24/3600 -> 0.35805556 | O28: ='1min_avg'!C24 -> 220.59 | P28: =SLOPE(O13:O43,N13:N43) -> 1.0472581 | R28: =INDEX($M$6:$M$15,MATCH(MAX(N28,0),$B$6:$B$15,1))+INDEX($J$6:$J$15,MATCH(MAX(N28,0),$B$6:$B$15,1))*MAX(N28,0) -> 220.47245
N29: ='1min_avg'!B25/3600 -> 0.37472222 | O29: ='1min_avg'!C25 -> 220.29333 | P29: =SLOPE(O14:O44,N14:N44) -> 1.0312097 | R29: =INDEX($M$6:$M$15,MATCH(MAX(N29,0),$B$6:$B$15,1))+INDEX($J$6:$J$15,MATCH(MAX(N29,0),$B$6:$B$15,1))*MAX(N29,0) -> 220.48881
N30: ='1min_avg'!B26/3600 -> 0.39138889 | O30: ='1min_avg'!C26 -> 220.63667 | P30: =SLOPE(O15:O45,N15:N45) -> 0.90120968 | R30: =INDEX($M$6:$M$15,MATCH(MAX(N30,0),$B$6:$B$15,1))+INDEX($J$6:$J$15,MATCH(MAX(N30,0),$B$6:$B$15,1))*MAX(N30,0) -> 220.50516
N31: ='1min_avg'!B27/3600 -> 0.40805556 | O31: ='1min_avg'!C27 -> 220.63333 | P31: =SLOPE(O16:O46,N16:N46) -> 0.76072581 | R31: =INDEX($M$6:$M$15,MATCH(MAX(N31,0),$B$6:$B$15,1))+INDEX($J$6:$J$15,MATCH(MAX(N31,0),$B$6:$B$15,1))*MAX(N31,0) -> 220.52152
N32: ='1min_avg'!B28/3600 -> 0.42472222 | O32: ='1min_avg'!C28 -> 220.70333 | P32: =SLOPE(O17:O47,N17:N47) -> 0.6525 | R32: =INDEX($M$6:$M$15,MATCH(MAX(N32,0),$B$6:$B$15,1))+INDEX($J$6:$J$15,MATCH(MAX(N32,0),$B$6:$B$15,1))*MAX(N32,0) -> 220.53787
... N65: ='1min_avg'!B61/3600 -> 0.97472222 | O65: ='1min_avg'!C61 -> 220.81667 | P65: =SLOPE(O50:O80,N50:N80) -> 0.42290323 | R65: =INDEX($M$6:$M$15,MATCH(MAX(N65,0),$B$6:$B$15,1))+INDEX($J$6:$J$15,MATCH(MAX(N65,0),$B$6:$B$15,1))*MAX(N65,0) -> 220.675
N66: ='1min_avg'!B62/3600 -> 0.99138889 | O66: ='1min_avg'!C62 -> 220.74667 | P66: =SLOPE(O51:O81,N51:N81) -> 0.34612903 | Q66: =SLOPE(O6:O126,N6:N126) -> 0.37453326 | R66: =INDEX($M$6:$M$15,MATCH(MAX(N66,0),$B$6:$B$15,1))+INDEX($J$6:$J$15,MATCH(MAX(N66,0),$B$6:$B$15,1))*MAX(N66,0) -> 220.67682
N67: ='1min_avg'!B63/3600 -> 1.0080556 | O67: ='1min_avg'!C63 -> 220.79333 | P67: =SLOPE(O52:O82,N52:N82) -> 0.35508065 | Q67: =SLOPE(O7:O127,N7:N127) -> 0.36941607 | R67: =INDEX($M$6:$M$15,MATCH(MAX(N67,0),$B$6:$B$15,1))+INDEX($J$6:$J$15,MATCH(MAX(N67,0),$B$6:$B$15,1))*MAX(N67,0) -> 220.78646
N68: ='1min_avg'!B64/3600 -> 1.0247222 | O68: ='1min_avg'!C64 -> 220.67333 | P68: =SLOPE(O53:O83,N53:N83) -> 0.38016129 | Q68: =SLOPE(O8:O128,N8:N128) -> 0.36736757 | R68: =INDEX($M$6:$M$15,MATCH(MAX(N68,0),$B$6:$B$15,1))+INDEX($J$6:$J$15,MATCH(MAX(N68,0),$B$6:$B$15,1))*MAX(N68,0) -> 220.7895
N69: ='1min_avg'!B65/3600 -> 1.0413889 | O69: ='1min_avg'!C65 -> 220.81333 | P69: =SLOPE(O54:O84,N54:N84) -> 0.41016129 | Q69: =SLOPE(O9:O129,N9:N129) -> 0.3633952 | R69: =INDEX($M$6:$M$15,MATCH(MAX(N69,0),$B$6:$B$15,1))+INDEX($J$6:$J$15,MATCH(MAX(N69,0),$B$6:$B$15,1))*MAX(N69,0) -> 220.79254
A70: How to read these two panels (same time axis) | N70: ='1min_avg'!B66/3600 -> 1.0580556 | O70: ='1min_avg'!C66 -> 220.69667 | P70: =SLOPE(O55:O85,N55:N85) -> 0.4225 | Q70: =SLOPE(O10:O130,N10:N130) -> 0.3632692 | R70: =INDEX($M$6:$M$15,MATCH(MAX(N70,0),$B$6:$B$15,1))+INDEX($J$6:$J$15,MATCH(MAX(N70,0),$B$6:$B$15,1))*MAX(N70,0) -> 220.79559
A71: STEP 1 = the original EC vs time curve (blue) with one straight line fitted to each time segment (red). The red line is the eye-fit made numeric. | N71: ='1min_avg'!B67/3600 -> 1.0747222 | O71: ='1min_avg'!C67 -> 220.7 | P71: =SLOPE(O56:O86,N56:N86) -> 0.44822581 | Q71: =SLOPE(O11:O131,N11:N131) -> 0.359622 | R71: =INDEX($M$6:$M$15,MATCH(MAX(N71,0),$B$6:$B$15,1))+INDEX($J$6:$J$15,MATCH(MAX(N71,0),$B$6:$B$15,1))*MAX(N71,0) -> 220.79863
A72: STEP 2 = the slope of those lines, plotted continuously. A steep part of the top panel becomes a high value in the bottom panel; a flat part becomes a low value. | N72: ='1min_avg'!B68/3600 -> 1.0913889 | O72: ='1min_avg'!C68 -> 220.83 | P72: =SLOPE(O57:O87,N57:N87) -> 0.46741935 | Q72: =SLOPE(O12:O132,N12:N132) -> 0.33578377 | R72: =INDEX($M$6:$M$15,MATCH(MAX(N72,0),$B$6:$B$15,1))+INDEX($J$6:$J$15,MATCH(MAX(N72,0),$B$6:$B$15,1))*MAX(N72,0) -> 220.80167
A73: Key message: the first 30 min run at ~1.0 µS/cm/h; after ~2 h the system settles to a slow, steady drift of 0.07–0.18 µS/cm/h that never reverses. | N73: ='1min_avg'!B69/3600 -> 1.1080556 | O73: ='1min_avg'!C69 -> 220.81667 | P73: =SLOPE(O58:O88,N58:N88) -> 0.42693548 | Q73: =SLOPE(O13:O133,N13:N133) -> 0.33142393 | R73: =INDEX($M$6:$M$15,MATCH(MAX(N73,0),$B$6:$B$15,1))+INDEX($J$6:$J$15,MATCH(MAX(N73,0),$B$6:$B$15,1))*MAX(N73,0) -> 220.80471
...

Sheet raw_data
A1: timestamp | B1: time_s | C1: EC_uScm | D1: Tw_C | E1: Salinity_ppm | F1: TDS_ppm | G1: pH | H1: pH_mV | I1: rs485_ok
A2: 2026-07-21 17:19:31 | B2: 0 | C2: 220.6 | D2: 22.2 | E2: 104 | F2: 104 | G2: 6.7475 | H2: 1570 | I2: 1
A3: 2026-07-21 17:19:33 | B3: 2 | C3: 220.6 | D3: 22.2 | E3: 104 | F3: 104 | G3: 6.7483333 | H3: 1571 | I3: 1
A4: 2026-07-21 17:19:35 | B4: 4 | C4: 220.5 | D4: 22.2 | E4: 104 | F4: 104 | G4: 6.7533333 | H4: 1569 | I4: 1
A5: 2026-07-21 17:19:37 | B5: 6 | C5: 219.8 | D5: 22.2 | E5: 104 | F5: 104 | G5: 6.7566667 | H5: 1568 | I5: 1
A6: 2026-07-21 17:19:39 | B6: 8 | C6: 220.4 | D6: 22.2 | E6: 104 | F6: 104 | G6: 6.7633333 | H6: 1567 | I6: 1
A7: 2026-07-21 17:19:41 | B7: 10 | C7: 219.9 | D7: 22.2 | E7: 104 | F7: 104 | G7: 6.7666667 | H7: 1566 | I7: 1
A8: 2026-07-21 17:19:43 | B8: 12 | C8: 220.5 | D8: 22.2 | E8: 104 | F8: 104 | G8: 6.7666667 | H8: 1566 | I8: 1
A9: 2026-07-21 17:19:45 | B9: 14 | C9: 220.3 | D9: 22.2 | E9: 104 | F9: 104 | G9: 6.7633333 | H9: 1567 | I9: 1
A10: 2026-07-21 17:19:47 | B10: 16 | C10: 219.8 | D10: 22.2 | E10: 104 | F10: 104 | G10: 6.76 | H10: 1567 | I10: 1
A11: 2026-07-21 17:19:49 | B11: 18 | C11: 220.4 | D11: 22.2 | E11: 104 | F11: 104 | G11: 6.76 | H11: 1567 | I11: 1
A12: 2026-07-21 17:19:51 | B12: 20 | C12: 219 | D12: 22.2 | E12: 104 | F12: 104 | G12: 6.7566667 | H12: 1568 | I12: 1
A13: 2026-07-21 17:19:53 | B13: 22 | C13: 220.5 | D13: 22.2 | E13: 104 | F13: 104 | G13: 6.7533333 | H13: 1570 | I13: 1
... A30631: 2026-07-22 10:20:20 | B30631: 61249 | C30631: 222.4 | D30631: 20.2 | E30631: 105 | F30631: 105 | G30631: 6.77 | H30631: 1566 | I30631: 1

Sheet Crank_Diffusion
A1: Crank Diffusion Model — Diffusion Coefficient (D) from EC Release Curve
A2: Source: 1min_avg (n=1022, 17.0 h, 2026-07-21 17:19 → 2026-07-22 10:20). EC range only 3.1 µS/cm and still rising — see caveat in A30.
R3: 4) Fit-window sensitivity — upper Mt/M∞ limit
A4: 1) Assumptions / Inputs | G4: t (s) | H4: t (h) | I4: EC (µS/cm) | J4: Mt/M∞ | K4: ln(1 - Mt/M∞) | L4: Crank fit (extrapolated) | N4: t (h) | O4: ln(1 - Mt/M∞) | P4: Crank fit (extrapolated) | R4: Upper Mt/M∞ | S4: Row end | T4: t end (h) | U4: n pts | V4: Slope m (1/s) | W4: Intercept c | X4: R² | Y4: |c − ln(6/π²)| | Z4: D (cm²/s)
A5: Particle diameter (µm) | B5: 1.8 | G5: ='1min_avg'!B2-'1min_avg'!$B$2 -> 0 | H5: =G5/3600 -> 0 | I5: ='1min_avg'!C2 -> 220.2 | J5: =(I5-$B$8)/($B$9-$B$8) -> 0 | K5: =IF(J5<1,LN(1-J5),NA()) -> 0 | L5: =$B$20+$B$19*G5 -> -0.12372125 | N5: =H5 -> 0 | O5: =K5 -> 0 | P5: =L5 -> -0.12372125 | R5: 0.4 | S5: =MATCH($R5,$J$5:$J$1026,1)+4 -> 197 | T5: {=INDEX($H:$H,$S5)} -> 3.2 | U5: =$S5-$B$16+1 -> 179 | V5: =SLOPE(INDEX($K:$K,$B$16):INDEX($K:$K,$S5),INDEX($G:$G,$B$16):INDEX($G:$G,$S5)) -> -3.4440364e-05 | W5: =INTERCEPT(INDEX($K:$K,$B$16):INDEX($K:$K,$S5),INDEX($G:$G,$B$16):INDEX($G:$G,$S5)) -> -0.12610188 | X5: =RSQ(INDEX($K:$K,$B$16):INDEX($K:$K,$S5),INDEX($G:$G,$B$16):INDEX($G:$G,$S5)) -> 0.84855326 | Y5: =ABS($W5-$B$12) -> 0.37159842 | Z5: =-$V5*$B$7^2/PI()^2 -> 2.8265261e-14
A6: Particle radius r (µm) | B6: =B5/2 -> 0.9 | G6: ='1min_avg'!B3-'1min_avg'!$B$2 -> 60 | H6: =G6/3600 -> 0.016666667 | I6: ='1min_avg'!C3 -> 220.32333 | J6: =(I6-$B$8)/($B$9-$B$8) -> 0.052151851 | K6: =IF(J6<1,LN(1-J6),NA()) -> -0.05356097 | L6: =$B$20+$B$19*G6 -> -0.12574378 | N6: =H6 -> 0.016666667 | O6: =K6 -> -0.05356097 | P6: =L6 -> -0.12574378 | R6: 0.5 | S6: =MATCH($R6,$J$5:$J$1026,1)+4 -> 284 | T6: {=INDEX($H:$H,$S6)} -> 4.65 | U6: =$S6-$B$16+1 -> 266 | V6: =SLOPE(INDEX($K:$K,$B$16):INDEX($K:$K,$S6),INDEX($G:$G,$B$16):INDEX($G:$G,$S6)) -> -3.2039036e-05 | W6: =INTERCEPT(INDEX($K:$K,$B$16):INDEX($K:$K,$S6),INDEX($G:$G,$B$16):INDEX($G:$G,$S6)) -> -0.13842647 | X6: =RSQ(INDEX($K:$K,$B$16):INDEX($K:$K,$S6),INDEX($G:$G,$B$16):INDEX($G:$G,$S6)) -> 0.93583099 | Y6: =ABS($W6-$B$12) -> 0.35927383 | Z6: =-$V6*$B$7^2/PI()^2 -> 2.6294488e-14
A7: Particle radius r (cm) | B7: =B6/10000 -> 9e-05 | G7: ='1min_avg'!B4-'1min_avg'!$B$2 -> 120 | H7: =G7/3600 -> 0.033333333 | I7: ='1min_avg'!C4 -> 220.25333 | J7: =(I7-$B$8)/($B$9-$B$8) -> 0.022552152 | K7: =IF(J7<1,LN(1-J7),NA()) -> -0.022810341 | L7: =$B$20+$B$19*G7 -> -0.12776632 | N7: =H7 -> 0.033333333 | O7: =K7 -> -0.022810341 | P7: =L7 -> -0.12776632 | R7: 0.6 | S7: =MATCH($R7,$J$5:$J$1026,1)+4 -> 401 | T7: {=INDEX($H:$H,$S7)} -> 6.6 | U7: =$S7-$B$16+1 -> 383 | V7: =SLOPE(INDEX($K:$K,$B$16):INDEX($K:$K,$S7),INDEX($G:$G,$B$16):INDEX($G:$G,$S7)) -> -3.2506797e-05 | W7: =INTERCEPT(INDEX($K:$K,$B$16):INDEX($K:$K,$S7),INDEX($G:$G,$B$16):INDEX($G:$G,$S7)) -> -0.13463669 | X7: =RSQ(INDEX($K:$K,$B$16):INDEX($K:$K,$S7),INDEX($G:$G,$B$16):INDEX($G:$G,$S7)) -> 0.97618041 | Y7: =ABS($W7-$B$12) -> 0.36306361 | Z7: =-$V7*$B$7^2/PI()^2 -> 2.667838e-14
A8: EC0 — EC at first reading (µS/cm) | B8: ='1min_avg'!C2 -> 220.2 | G8: ='1min_avg'!B5-'1min_avg'!$B$2 -> 180 | H8: =G8/3600 -> 0.05 | I8: ='1min_avg'!C5 -> 220.45333 | J8: =(I8-$B$8)/($B$9-$B$8) -> 0.10712272 | K8: =IF(J8<1,LN(1-J8),NA()) -> -0.11330613 | L8: =$B$20+$B$19*G8 -> -0.12978886 | N8: =H8 -> 0.05 | O8: =K8 -> -0.11330613 | P8: =L8 -> -0.12978886 | R8: 0.7 | S8: =MATCH($R8,$J$5:$J$1026,1)+4 -> 538 | T8: {=INDEX($H:$H,$S8)} -> 8.8833333 | U8: =$S8-$B$16+1 -> 520 | V8: =SLOPE(INDEX($K:$K,$B$16):INDEX($K:$K,$S8),INDEX($G:$G,$B$16):INDEX($G:$G,$S8)) -> -3.3727182e-05 | W8: =INTERCEPT(INDEX($K:$K,$B$16):INDEX($K:$K,$S8),INDEX($G:$G,$B$16):INDEX($G:$G,$S8)) -> -0.12388326 | X8: =RSQ(INDEX($K:$K,$B$16):INDEX($K:$K,$S8),INDEX($G:$G,$B$16):INDEX($G:$G,$S8)) -> 0.98770314 | Y8: =ABS($W8-$B$12) -> 0.37381704 | Z8: =-$V8*$B$7^2/PI()^2 -> 2.7679952e-14
A9: EC∞ — assumed plateau (µS/cm) ← adjustable | B9: =AVERAGE('1min_avg'!C994:C1023) -> 222.56489 | G9: ='1min_avg'!B6-'1min_avg'!$B$2 -> 240 | H9: =G9/3600 -> 0.066666667 | I9: ='1min_avg'!C6 -> 220.29333 | J9: =(I9-$B$8)/($B$9-$B$8) -> 0.039466266 | K9: =IF(J9<1,LN(1-J9),NA()) -> -0.040266176 | L9: =$B$20+$B$19*G9 -> -0.13181139 | N9: =H9 -> 0.066666667 | O9: =K9 -> -0.040266176 | P9: =L9 -> -0.13181139 | R9: 0.8 | S9: =MATCH($R9,$J$5:$J$1026,1)+4 -> 691 | T9: {=INDEX($H:$H,$S9)} -> 11.433333 | U9: =$S9-$B$16+1 -> 673 | V9: =SLOPE(INDEX($K:$K,$B$16):INDEX($K:$K,$S9),INDEX($G:$G,$B$16):INDEX($G:$G,$S9)) -> -3.3708954e-05 | W9: =INTERCEPT(INDEX($K:$K,$B$16):INDEX($K:$K,$S9),INDEX($G:$G,$B$16):INDEX($G:$G,$S9)) -> -0.12372125 | X9: =RSQ(INDEX($K:$K,$B$16):INDEX($K:$K,$S9),INDEX($G:$G,$B$16):INDEX($G:$G,$S9)) -> 0.99213444 | Y9: =ABS($W9-$B$12) -> 0.37397906 | Z9: =-$V9*$B$7^2/PI()^2 -> 2.7664992e-14
A10: Fit window — lower Mt/M∞ | B10: 0.1 | G10: ='1min_avg'!B7-'1min_avg'!$B$2 -> 300 | H10: =G10/3600 -> 0.083333333 | I10: ='1min_avg'!C7 -> 219.50667 | J10: =(I10-$B$8)/($B$9-$B$8) -> -0.29317797 | K10: =IF(J10<1,LN(1-J10),NA()) -> 0.25710273 | L10: =$B$20+$B$19*G10 -> -0.13383393 | N10: =H10 -> 0.083333333 | O10: =K10 -> 0.25710273 | P10: =L10 -> -0.13383393 | R10: 0.85 | S10: =MATCH($R10,$J$5:$J$1026,1)+4 -> 792 | T10: {=INDEX($H:$H,$S10)} -> 13.116667 | U10: =$S10-$B$16+1 -> 774 | V10: =SLOPE(INDEX($K:$K,$B$16):INDEX($K:$K,$S10),INDEX($G:$G,$B$16):INDEX($G:$G,$S10)) -> -3.5162223e-05 | W10: =INTERCEPT(INDEX($K:$K,$B$16):INDEX($K:$K,$S10),INDEX($G:$G,$B$16):INDEX($G:$G,$S10)) -> -0.1013295 | X10: =RSQ(INDEX($K:$K,$B$16):INDEX($K:$K,$S10),INDEX($G:$G,$B$16):INDEX($G:$G,$S10)) -> 0.9896419 | Y10: =ABS($W10-$B$12) -> 0.3963708 | Z10: =-$V10*$B$7^2/PI()^2 -> 2.8857692e-14
A11: Fit window — upper Mt/M∞ | B11: 0.8 | G11: ='1min_avg'!B8-'1min_avg'!$B$2 -> 360 | H11: =G11/3600 -> 0.1 | I11: ='1min_avg'!C8 -> 220.29 | J11: =(I11-$B$8)/($B$9-$B$8) -> 0.038056756 | K11: =IF(J11<1,LN(1-J11),NA()) -> -0.038799828 | L11: =$B$20+$B$19*G11 -> -0.13585647 | N11: =H11 -> 0.1 | O11: =K11 -> -0.038799828 | P11: =L11 -> -0.13585647
A12: Theoretical intercept ln(6/π²) | B12: =LN(6/PI()^2) -> -0.4977003 | G12: ='1min_avg'!B9-'1min_avg'!$B$2 -> 420 | H12: =G12/3600 -> 0.11666667 | I12: ='1min_avg'!C9 -> 220.17333 | J12: =(I12-$B$8)/($B$9-$B$8) -> -0.011276076 | K12: =IF(J12<1,LN(1-J12),NA()) -> 0.011212975 | L12: =$B$20+$B$19*G12 -> -0.13787901 | N12: =H12 -> 0.11666667 | O12: =K12 -> 0.011212975 | P12: =L12 -> -0.13787901
A13: Plateau noise SD, last 60 min (µS/cm) | B13: =STDEV('1min_avg'!C964:C1023) -> 0.04554128 | G13: ='1min_avg'!B10-'1min_avg'!$B$2 -> 480 | H13: =G13/3600 -> 0.13333333 | I13: ='1min_avg'!C10 -> 219.91667 | J13: =(I13-$B$8)/($B$9-$B$8) -> -0.11980831 | K13: =IF(J13<1,LN(1-J13),NA()) -> 0.11315752 | L13: =$B$20+$B$19*G13 -> -0.13990154 | N13: =H13 -> 0.13333333 | O13: =K13 -> 0.11315752 | P13: =L13 -> -0.13990154
G14: ='1min_avg'!B11-'1min_avg'!$B$2 -> 540 | H14: =G14/3600 -> 0.15 | I14: ='1min_avg'!C11 -> 219.99 | J14: =(I14-$B$8)/($B$9-$B$8) -> -0.088799098 | K14: =IF(J14<1,LN(1-J14),NA()) -> 0.085075344 | L14: =$B$20+$B$19*G14 -> -0.14192408 | N14: =H14 -> 0.15 | O14: =K14 -> 0.085075344 | P14: =L14 -> -0.14192408
A15: 2) Linear regression on ln(1 - Mt/M∞) vs t | G15: ='1min_avg'!B12-'1min_avg'!$B$2 -> 600 | H15: =G15/3600 -> 0.16666667 | I15: ='1min_avg'!C12 -> 220.40333 | J15: =(I15-$B$8)/($B$9-$B$8) -> 0.085980079 | K15: =IF(J15<1,LN(1-J15),NA()) -> -0.089902912 | L15: =$B$20+$B$19*G15 -> -0.14394662 | N15: =H15 -> 0.16666667 | O15: =K15 -> -0.089902912 | P15: =L15 -> -0.14394662
A16: Fit row start | B16: =MATCH($B$10,$J$5:$J$1026,1)+5 -> 19 | G16: ='1min_avg'!B13-'1min_avg'!$B$2 -> 660 | H16: =G16/3600 -> 0.18333333 | I16: ='1min_avg'!C13 -> 220.26667 | J16: =(I16-$B$8)/($B$9-$B$8) -> 0.02819019 | K16: =IF(J16<1,LN(1-J16),NA()) -> -0.028595162 | L16: =$B$20+$B$19*G16 -> -0.14596915 | N16: =H16 -> 0.18333333 | O16: =K16 -> -0.028595162 | P16: =L16 -> -0.14596915
A17: Fit row end | B17: =MATCH($B$11,$J$5:$J$1026,1)+4 -> 691 | G17: ='1min_avg'!B14-'1min_avg'!$B$2 -> 720 | H17: =G17/3600 -> 0.2 | I17: ='1min_avg'!C14 -> 220.34 | J17: =(I17-$B$8)/($B$9-$B$8) -> 0.059199399 | K17: =IF(J17<1,LN(1-J17),NA()) -> -0.061024063 | L17: =$B$20+$B$19*G17 -> -0.14799169 | N17: =H17 -> 0.2 | O17: =K17 -> -0.061024063 | P17: =L17 -> -0.14799169
A18: Fit window (h) | B18: {=TEXT(INDEX($H:$H,$B$16),"0.00")&" – "&TEXT(INDEX($H:$H,$B$17),"0.00")} -> 0.23 – 11.43 | G18: ='1min_avg'!B15-'1min_avg'!$B$2 -> 780 | H18: =G18/3600 -> 0.21666667 | I18: ='1min_avg'!C15 -> 220.37333 | J18: =(I18-$B$8)/($B$9-$B$8) -> 0.073294494 | K18: =IF(J18<1,LN(1-J18),NA()) -> -0.076119448 | L18: =$B$20+$B$19*G18 -> -0.15001423 | N18: =H18 -> 0.21666667 | O18: =K18 -> -0.076119448 | P18: =L18 -> -0.15001423
A19: Slope m (1/s) | B19: =SLOPE(INDEX($K:$K,$B$16):INDEX($K:$K,$B$17),INDEX($G:$G,$B$16):INDEX($G:$G,$B$17)) -> -3.3708954e-05 | G19: ='1min_avg'!B16-'1min_avg'!$B$2 -> 840 | H19: =G19/3600 -> 0.23333333 | I19: ='1min_avg'!C16 -> 220.48667 | J19: =(I19-$B$8)/($B$9-$B$8) -> 0.12121782 | K19: =IF(J19<1,LN(1-J19),NA()) -> -0.12921821 | L19: =$B$20+$B$19*G19 -> -0.15203677 | N19: =H19 -> 0.23333333 | O19: =K19 -> -0.12921821 | P19: =L19 -> -0.15203677
A20: Intercept c | B20: =INTERCEPT(INDEX($K:$K,$B$16):INDEX($K:$K,$B$17),INDEX($G:$G,$B$16):INDEX($G:$G,$B$17)) -> -0.12372125 | G20: ='1min_avg'!B17-'1min_avg'!$B$2 -> 900 | H20: =G20/3600 -> 0.25 | I20: ='1min_avg'!C17 -> 220.41667 | J20: =(I20-$B$8)/($B$9-$B$8) -> 0.091618117 | K20: =IF(J20<1,LN(1-J20),NA()) -> -0.096090413 | L20: =$B$20+$B$19*G20 -> -0.1540593 | N20: =H20 -> 0.25 | O20: =K20 -> -0.096090413 | P20: =L20 -> -0.1540593
A21: R² | B21: =RSQ(INDEX($K:$K,$B$16):INDEX($K:$K,$B$17),INDEX($G:$G,$B$16):INDEX($G:$G,$B$17)) -> 0.99213444 | G21: ='1min_avg'!B18-'1min_avg'!$B$2 -> 960 | H21: =G21/3600 -> 0.26666667 | I21: ='1min_avg'!C18 -> 220.39333 | J21: =(I21-$B$8)/($B$9-$B$8) -> 0.08175155 | K21: =IF(J21<1,LN(1-J21),NA()) -> -0.085287283 | L21: =$B$20+$B$19*G21 -> -0.15608184 | N21: =H21 -> 0.26666667 | O21: =K21 -> -0.085287283 | P21: =L21 -> -0.15608184
A22: n points in fit | B22: =$B$17-$B$16+1 -> 673 | G22: ='1min_avg'!B19-'1min_avg'!$B$2 -> 1020 | H22: =G22/3600 -> 0.28333333 | I22: ='1min_avg'!C19 -> 220 | J22: =(I22-$B$8)/($B$9-$B$8) -> -0.084570569 | K22: =IF(J22<1,LN(1-J22),NA()) -> 0.08118412 | L22: =$B$20+$B$19*G22 -> -0.15810438 | N22: =H22 -> 0.28333333 | O22: =K22 -> 0.08118412 | P22: =L22 -> -0.15810438
G23: ='1min_avg'!B20-'1min_avg'!$B$2 -> 1080 | H23: =G23/3600 -> 0.3 | I23: ='1min_avg'!C20 -> 220.55 | J23: =(I23-$B$8)/($B$9-$B$8) -> 0.1479985 | K23: =IF(J23<1,LN(1-J23),NA()) -> -0.16016699 | L23: =$B$20+$B$19*G23 -> -0.16012692 | N23: =H23 -> 0.3 | O23: =K23 -> -0.16016699 | P23: =L23 -> -0.16012692
A24: 3) Diffusion coefficient | G24: ='1min_avg'!B21-'1min_avg'!$B$2 -> 1140 | H24: =G24/3600 -> 0.31666667 | I24: ='1min_avg'!C21 -> 220.55 | J24: =(I24-$B$8)/($B$9-$B$8) -> 0.1479985 | K24: =IF(J24<1,LN(1-J24),NA()) -> -0.16016699 | L24: =$B$20+$B$19*G24 -> -0.16214945 | N24: =H24 -> 0.31666667 | O24: =K24 -> -0.16016699 | P24: =L24 -> -0.16214945
A25: D = -m·r²/π² (cm²/s) | B25: =-$B$19*$B$7^2/PI()^2 -> 2.7664992e-14 | G25: ='1min_avg'!B22-'1min_avg'!$B$2 -> 1200 | H25: =G25/3600 -> 0.33333333 | I25: ='1min_avg'!C22 -> 220.52667 | J25: =(I25-$B$8)/($B$9-$B$8) -> 0.13813193 | K25: =IF(J25<1,LN(1-J25),NA()) -> -0.14865307 | L25: =$B$20+$B$19*G25 -> -0.16417199 | N25: =H25 -> 0.33333333 | O25: =K25 -> -0.14865307 | P25: =L25 -> -0.16417199
A26: D (m²/s) | B26: =B25/10000 -> 2.7664992e-18 | G26: ='1min_avg'!B23-'1min_avg'!$B$2 -> 1260 | H26: =G26/3600 -> 0.35 | I26: ='1min_avg'!C23 -> 220.53667 | J26: =(I26-$B$8)/($B$9-$B$8) -> 0.14236046 | K26: =IF(J26<1,LN(1-J26),NA()) -> -0.15357138 | L26: =$B$20+$B$19*G26 -> -0.16619453 | N26: =H26 -> 0.35 | O26: =K26 -> -0.15357138 | P26: =L26 -> -0.16619453
A27: Characteristic time r²/(π²D) (h) | B27: =-1/$B$19/3600 -> 8.2404747 | G27: ='1min_avg'!B24-'1min_avg'!$B$2 -> 1320 | H27: =G27/3600 -> 0.36666667 | I27: ='1min_avg'!C24 -> 220.59 | J27: =(I27-$B$8)/($B$9-$B$8) -> 0.16491261 | K27: =IF(J27<1,LN(1-J27),NA()) -> -0.1802189 | L27: =$B$20+$B$19*G27 -> -0.16821706 | N27: =H27 -> 0.36666667 | O27: =K27 -> -0.1802189 | P27: =L27 -> -0.16821706
G28: ='1min_avg'!B25-'1min_avg'!$B$2 -> 1380 | H28: =G28/3600 -> 0.38333333 | I28: ='1min_avg'!C25 -> 220.29333 | J28: =(I28-$B$8)/($B$9-$B$8) -> 0.039466266 | K28: =IF(J28<1,LN(1-J28),NA()) -> -0.040266176 | L28: =$B$20+$B$19*G28 -> -0.1702396 | N28: =H28 -> 0.38333333 | O28: =K28 -> -0.040266176 | P28: =L28 -> -0.1702396
G29: ='1min_avg'!B26-'1min_avg'!$B$2 -> 1440 | H29: =G29/3600 -> 0.4 | I29: ='1min_avg'!C26 -> 220.63667 | J29: =(I29-$B$8)/($B$9-$B$8) -> 0.18464574 | K29: =IF(J29<1,LN(1-J29),NA()) -> -0.20413259 | L29: =$B$20+$B$19*G29 -> -0.17226214 | N29: =H29 -> 0.4 | O29: =K29 -> -0.20413259 | P29: =L29 -> -0.17226214
A30: ⚠ CAVEAT — this run never reached steady state. EC rose 220.2 → 222.6 µS/cm (range 3.1) and was still climbing ~0.09 µS/cm/h at 17 h, vs plateau noise SD of only 0.046. EC∞ in B9 is therefore a LOWER-BOUND guess (mean of last 30 min), not a measured plateau. | G30: ='1min_avg'!B27-'1min_avg'!$B$2 -> 1500 | H30: =G30/3600 -> 0.41666667 | I30: ='1min_avg'!C27 -> 220.63333 | J30: =(I30-$B$8)/($B$9-$B$8) -> 0.18323623 | K30: =IF(J30<1,LN(1-J30),NA()) -> -0.20240537 | L30: =$B$20+$B$19*G30 -> -0.17428468 | N30: =H30 -> 0.41666667 | O30: =K30 -> -0.20240537 | P30: =L30 -> -0.17428468
A31: Consequence: D is roughly proportional to 1/(EC∞ - EC0). If the true plateau is higher than 222.56, the real D is SMALLER than reported. Type a different EC∞ in the yellow cell B9 to test scenarios — everything recalculates. | G31: ='1min_avg'!B28-'1min_avg'!$B$2 -> 1560 | H31: =G31/3600 -> 0.43333333 | I31: ='1min_avg'!C28 -> 220.70333 | J31: =(I31-$B$8)/($B$9-$B$8) -> 0.21283593 | K31: =IF(J31<1,LN(1-J31),NA()) -> -0.23931858 | L31: =$B$20+$B$19*G31 -> -0.17630721 | N31: =H31 -> 0.43333333 | O31: =K31 -> -0.23931858 | P31: =L31 -> -0.17630721
A32: Adjustable inputs: B5 particle size, B9 assumed plateau, B10/B11 fit window. All results below are formulas. | G32: ='1min_avg'!B29-'1min_avg'!$B$2 -> 1620 | H32: =G32/3600 -> 0.45 | I32: ='1min_avg'!C29 -> 220.47333 | J32: =(I32-$B$8)/($B$9-$B$8) -> 0.11557978 | K32: =IF(J32<1,LN(1-J32),NA()) -> -0.12282297 | L32: =$B$20+$B$19*G32 -> -0.17832975 | N32: =H32 -> 0.45 | O32: =K32 -> -0.12282297 | P32: =L32 -> -0.17832975
G33: ='1min_avg'!B30-'1min_avg'!$B$2 -> 1680 | H33: =G33/3600 -> 0.46666667 | I33: ='1min_avg'!C30 -> 220.22333 | J33: =(I33-$B$8)/($B$9-$B$8) -> 0.0098665664 | K33: =IF(J33<1,LN(1-J33),NA()) -> -0.0099155636 | L33: =$B$20+$B$19*G33 -> -0.18035229 | N33: =H33 -> 0.46666667 | O33: =K33 -> -0.0099155636 | P33: =L33 -> -0.18035229
G34: ='1min_avg'!B31-'1min_avg'!$B$2 -> 1740 | H34: =G34/3600 -> 0.48333333 | I34: ='1min_avg'!C31 -> 220.65 | J34: =(I34-$B$8)/($B$9-$B$8) -> 0.19028378 | K34: =IF(J34<1,LN(1-J34),NA()) -> -0.21107144 | L34: =$B$20+$B$19*G34 -> -0.18237482 | N34: =H34 -> 0.48333333 | O34: =K34 -> -0.21107144 | P34: =L34 -> -0.18237482
G35: ='1min_avg'!B32-'1min_avg'!$B$2 -> 1800 | H35: =G35/3600 -> 0.5 | I35: ='1min_avg'!C32 -> 220.65 | J35: =(I35-$B$8)/($B$9-$B$8) -> 0.19028378 | K35: =IF(J35<1,LN(1-J35),NA()) -> -0.21107144 | L35: =$B$20+$B$19*G35 -> -0.18439736 | N35: =H35 -> 0.5 | O35: =K35 -> -0.21107144 | P35: =L35 -> -0.18439736
G36: ='1min_avg'!B33-'1min_avg'!$B$2 -> 1860 | H36: =G36/3600 -> 0.51666667 | I36: ='1min_avg'!C33 -> 220.78 | J36: =(I36-$B$8)/($B$9-$B$8) -> 0.24525465 | K36: =IF(J36<1,LN(1-J36),NA()) -> -0.28137487 | L36: =$B$20+$B$19*G36 -> -0.1864199 | N36: =H36 -> 0.51666667 | O36: =K36 -> -0.28137487 | P36: =L36 -> -0.1864199
G37: ='1min_avg'!B34-'1min_avg'!$B$2 -> 1920 | H37: =G37/3600 -> 0.53333333 | I37: ='1min_avg'!C34 -> 220.66333 | J37: =(I37-$B$8)/($B$9-$B$8) -> 0.19592182 | K37: =IF(J37<1,LN(1-J37),NA()) -> -0.21805877 | L37: =$B$20+$B$19*G37 -> -0.18844244 | N37: =H37 -> 0.53333333 | O37: =K37 -> -0.21805877 | P37: =L37 -> -0.18844244
G38: ='1min_avg'!B35-'1min_avg'!$B$2 -> 1980 | H38: =G38/3600 -> 0.55 | I38: ='1min_avg'!C35 -> 220.71 | J38: =(I38-$B$8)/($B$9-$B$8) -> 0.21565495 | K38: =IF(J38<1,LN(1-J38),NA()) -> -0.24290624 | L38: =$B$20+$B$19*G38 -> -0.19046497 | N38: =H38 -> 0.55 | O38: =K38 -> -0.24290624 | P38: =L38 -> -0.19046497
G39: ='1min_avg'!B36-'1min_avg'!$B$2 -> 2040 | H39: =G39/3600 -> 0.56666667 | I39: ='1min_avg'!C36 -> 220.62333 | J39: =(I39-$B$8)/($B$9-$B$8) -> 0.17900771 | K39: =IF(J39<1,LN(1-J39),NA()) -> -0.19724155 | L39: =$B$20+$B$19*G39 -> -0.19248751 | N39: =H39 -> 0.56666667 | O39: =K39 -> -0.19724155 | P39: =L39 -> -0.19248751
G40: ='1min_avg'!B37-'1min_avg'!$B$2 -> 2100 | H40: =G40/3600 -> 0.58333333 | I40: ='1min_avg'!C37 -> 220.53667 | J40: =(I40-$B$8)/($B$9-$B$8) -> 0.14236046 | K40: =IF(J40<1,LN(1-J40),NA()) -> -0.15357138 | L40: =$B$20+$B$19*G40 -> -0.19451005 | N40: =H40 -> 0.58333333 | O40: =K40 -> -0.15357138 | P40: =L40 -> -0.19451005
...
